<?xml version="1.0" ?>
<robot name="navbot006" xmlns:xacro="http://www.ros.org/wiki/xacro">

<xacro:include filename="$(find navbot006_description)/urdf/materials.xacro" />
<xacro:include filename="$(find navbot006_description)/urdf/navbot006.trans" />
<xacro:include filename="$(find navbot006_description)/urdf/navbot006.gazebo" />
<link name="base_link">
  <inertial>
    <origin rpy="0 0 0" xyz="-0.000214045237661271 6.88514928563836e-17 0.03222963789389715"/>
    <mass value="0.7001041980964979"/>
    <inertia ixx="0.001274" ixy="-0.0" ixz="-0.0" iyy="0.002205" iyz="0.0" izz="0.003356"/>
  </inertial>
  <visual>
    <origin rpy="0 0 0" xyz="0 0 0"/>
    <geometry>
      <mesh filename="package://navbot006_description/meshes/base_link.stl" scale="0.001 0.001 0.001"/>
    </geometry>
    <material name="body_color"/>
  </visual>
  <collision>
    <origin rpy="0 0 0" xyz="0 0 0"/>
    <geometry>
      <mesh filename="package://navbot006_description/meshes/base_link.stl" scale="0.001 0.001 0.001"/>
    </geometry>
  </collision>
</link>

<link name="left_wheel_1">
  <inertial>
    <origin rpy="0 0 0" xyz="-1.491862189340054e-14 0.009999999999999912 0.0"/>
    <mass value="0.006597344572538555"/>
    <inertia ixx="2e-06" ixy="0.0" ixz="0.0" iyy="3e-06" iyz="0.0" izz="2e-06"/>
  </inertial>
  <visual>
    <origin rpy="0 0 0" xyz="0.09 -0.085 -0.03"/>
    <geometry>
      <mesh filename="package://navbot006_description/meshes/left_wheel_1.stl" scale="0.001 0.001 0.001"/>
    </geometry>
    <material name="black"/>
  </visual>
  <collision>
    <origin rpy="0 0 0" xyz="0.09 -0.085 -0.03"/>
    <geometry>
      <mesh filename="package://navbot006_description/meshes/left_wheel_1.stl" scale="0.001 0.001 0.001"/>
    </geometry>
  </collision>
</link>

<link name="right_wheel_1">
  <inertial>
    <origin rpy="0 0 0" xyz="-1.494637746901617e-14 -0.009999999999999926 0.0"/>
    <mass value="0.006597344572538555"/>
    <inertia ixx="2e-06" ixy="0.0" ixz="0.0" iyy="3e-06" iyz="0.0" izz="2e-06"/>
  </inertial>
  <visual>
    <origin rpy="0 0 0" xyz="0.09 0.085 -0.03"/>
    <geometry>
      <mesh filename="package://navbot006_description/meshes/right_wheel_1.stl" scale="0.001 0.001 0.001"/>
    </geometry>
    <material name="black"/>
  </visual>
  <collision>
    <origin rpy="0 0 0" xyz="0.09 0.085 -0.03"/>
    <geometry>
      <mesh filename="package://navbot006_description/meshes/right_wheel_1.stl" scale="0.001 0.001 0.001"/>
    </geometry>
  </collision>
</link>

<link name="lidar_top_1">
  <inertial>
    <origin rpy="0 0 0" xyz="-3.618764437576268e-18 -7.237528875152536e-18 0.0050000000000000044"/>
    <mass value="0.1541343895667492"/>
    <inertia ixx="2.5e-05" ixy="-0.0" ixz="-0.0" iyy="2.5e-05" iyz="-0.0" izz="4.8e-05"/>
  </inertial>
  <visual>
    <origin rpy="0 0 0" xyz="-0.0 -0.0 -0.07"/>
    <geometry>
      <mesh filename="package://navbot006_description/meshes/lidar_top_1.stl" scale="0.001 0.001 0.001"/>
    </geometry>
    <material name="blue"/>
  </visual>
  <collision>
    <origin rpy="0 0 0" xyz="-0.0 -0.0 -0.07"/>
    <geometry>
      <mesh filename="package://navbot006_description/meshes/lidar_top_1.stl" scale="0.001 0.001 0.001"/>
    </geometry>
  </collision>
</link>

<link name="castor_w_1">
  <inertial>
    <origin rpy="0 0 0" xyz="-0.020000000000627446 8.03980839710679e-17 -0.008499999999999982"/>
    <mass value="0.005550147021341895"/>
    <inertia ixx="0.0" ixy="0.0" ixz="0.0" iyy="0.0" iyz="-0.0" izz="0.0"/>
  </inertial>
  <visual>
    <origin rpy="0 0 0" xyz="-0.1 -0.0 -0.02"/>
    <geometry>
      <mesh filename="package://navbot006_description/meshes/castor_w_1.stl" scale="0.001 0.001 0.001"/>
    </geometry>
    <material name="body_color"/>
  </visual>
  <collision>
    <origin rpy="0 0 0" xyz="-0.1 -0.0 -0.02"/>
    <geometry>
      <mesh filename="package://navbot006_description/meshes/castor_w_1.stl" scale="0.001 0.001 0.001"/>
    </geometry>
  </collision>
</link>

<link name="rasp_pi__1__1">
  <inertial>
    <origin rpy="0 0 0" xyz="0.028745991634913592 0.002534527480267408 0.004888830680916854"/>
    <mass value="0.13472167579144473"/>
    <inertia ixx="8.3e-05" ixy="0.0" ixz="0.0" iyy="4.1e-05" iyz="9e-06" izz="0.000118"/>
  </inertial>
  <visual>
    <origin rpy="0 0 0" xyz="0.1 -0.0 -0.04"/>
    <geometry>
      <mesh filename="package://navbot006_description/meshes/rasp_pi__1__1.stl" scale="0.001 0.001 0.001"/>
    </geometry>
    <material name="body_color"/>
  </visual>
  <collision>
    <origin rpy="0 0 0" xyz="0.1 -0.0 -0.04"/>
    <geometry>
      <mesh filename="package://navbot006_description/meshes/rasp_pi__1__1.stl" scale="0.001 0.001 0.001"/>
    </geometry>
  </collision>
</link>

<joint name="left_joint" type="continuous">
  <origin rpy="0 0 0" xyz="-0.09 0.085 0.03"/>
  <parent link="base_link"/>
  <child link="left_wheel_1"/>
  <axis xyz="0.0 1.0 0.0"/>
</joint>

<joint name="right_joint" type="continuous">
  <origin rpy="0 0 0" xyz="-0.09 -0.085 0.03"/>
  <parent link="base_link"/>
  <child link="right_wheel_1"/>
  <axis xyz="0.0 1.0 0.0"/>
</joint>

<joint name="Rigid8" type="fixed">
  <origin rpy="0 0 0" xyz="0.0 0.0 0.07"/>
  <parent link="base_link"/>
  <child link="lidar_top_1"/>
</joint>

<joint name="Rigid9" type="fixed">
  <origin rpy="0 0 0" xyz="0.1 0.0 0.02"/>
  <parent link="base_link"/>
  <child link="castor_w_1"/>
</joint>

<joint name="Rigid10" type="fixed">
  <origin rpy="0 0 0" xyz="-0.1 0.0 0.04"/>
  <parent link="base_link"/>
  <child link="rasp_pi__1__1"/>
</joint>

</robot>
